2025-03-24 04:50:26.291 | INFO     | __main__:test_call_graph_parse:185 - Testing AsyncCallGraph parse() method
2025-03-24 04:50:26.291 | INFO     | __main__:test_call_graph_parse:195 - Using base_dir: /home/files/git/a-finite-monkey-engine
2025-03-24 04:50:26.291 | INFO     | __main__:test_call_graph_parse:196 - Using src_dir: tests/fixtures/call_graph
2025-03-24 04:50:26.291 | ERROR    | __main__:test_call_graph_parse:265 - Error testing call graph: [Errno 2] No such file or directory: '/home/files/git/a-finite-monkey-engine/finite_monkey/utils/whitelist.json'
2025-03-24 04:50:26.293 | ERROR    | __main__:test_call_graph_parse:267 - Traceback (most recent call last):
  File "/home/files/git/a-finite-monkey-engine/./scripts/test_call_graph.py", line 202, in test_call_graph_parse
    await call_graph.parse()
  File "/home/files/git/a-finite-monkey-engine/finite_monkey/utils/async_call_graph.py", line 563, in parse
    self.cg =  await self.create(root=path.join(config.base_dir, config.src_dir))
               ^^^^^^^^^^^^^^^^^^^^^^^^^^^^^^^^^^^^^^^^^^^^^^^^^^^^^^^^^^^^^^^^^^
  File "/home/files/git/a-finite-monkey-engine/finite_monkey/utils/async_call_graph.py", line 54, in create
    async with aiofiles.open(os.path.join(current_path, "whitelist.json"), "r") as f:
               ^^^^^^^^^^^^^^^^^^^^^^^^^^^^^^^^^^^^^^^^^^^^^^^^^^^^^^^^^^^^^^^^
  File "/home/files/git/a-finite-monkey-engine/.venv/lib/python3.12/site-packages/aiofiles/base.py", line 63, in __aenter__
    return await self
           ^^^^^^^^^^
  File "/home/files/git/a-finite-monkey-engine/.venv/lib/python3.12/site-packages/aiofiles/base.py", line 59, in __await__
    self._obj = yield from self._coro.__await__()
                ^^^^^^^^^^^^^^^^^^^^^^^^^^^^^^^^^
  File "/home/files/git/a-finite-monkey-engine/.venv/lib/python3.12/site-packages/aiofiles/threadpool/__init__.py", line 92, in _open
    f = await loop.run_in_executor(executor, cb)
        ^^^^^^^^^^^^^^^^^^^^^^^^^^^^^^^^^^^^^^^^
  File "/home/files/.local/share/uv/python/cpython-3.12.9-linux-x86_64-gnu/lib/python3.12/concurrent/futures/thread.py", line 59, in run
    result = self.fn(*self.args, **self.kwargs)
             ^^^^^^^^^^^^^^^^^^^^^^^^^^^^^^^^^^
FileNotFoundError: [Errno 2] No such file or directory: '/home/files/git/a-finite-monkey-engine/finite_monkey/utils/whitelist.json'

2025-03-24 04:50:26.293 | ERROR    | __main__:main:314 - ‚ùå AsyncCallGraph test FAILED
